Workbook

Sheet DRA. ALEJANDRA
A6: DRA. ALEJANDRA
A7: FECHA | B7: NOMBRE DEL PACIENTE | C7: TIPO DE CONSULTA | D7: MONTO | E7: MEDIO DE PAGO | F7: FACTURADO | G7: NÚMERO RECIBO | H7: NÚMERO FACTURA | I7: FUENTE | J7: OBSERVACIONES | K7: Columna1
A8: 46144 | B8: Julio Aguilar | C8: transplante | D8: 100000 | E8: TARJETA CREDITO | F8: si
A9: 46146 | B9: Paola Huelga Correa | C9: subsecuetne | D9: 1800 | E9: AMEX | F9: no | J9: se cobro dr.Barrera 7/5/26
A10: 46146 | B10: Paola Huelga Correa | C10: AG gel + 1 vastionin | D10: 1500 | E10: AMEX | F10: no | J10: se cobro dr.Barrera
A11: 46146 | B11: Esteban Campos Valladolid | C11: procedimiento | D11: 2500 | E11: TARJETA CREDITO | F11: si
A12: 46146 | B12: KARLO IMANUEL GALINDO RAMIREZ | C12: Subsecuente | D12: 1800 | E12: TARJETA CREDITO | F12: NO
A13: 46146 | B13: Cecilia Valladolid | C13: Subsecuente | D13: 1800 | E13: TARJETA CREDITO | F13: si
A14: 46146 | B14: Marco Antonio Torres Pérez | C14: Subsecuente | D14: 0 | E14: CORTESÍA
A15: 46146 | B15: Rebeca Kababie | C15: Procedimiento | D15: 3500 | E15: TARJETA CREDITO | F15: no
A16: 46146 | B16: Fernando Terres | C16: CO2 | D16: 3000 | E16: TARJETA CREDITO
A17: 46146 | B17: Fernando Terres | C17: shampoo | D17: 1200 | E17: TARJETA CREDITO
A18: 46147 | B18: Cecilia Ramírez Suttclife | C18: subsecuente | D18: 1800 | E18: AMEX | F18: si
A19: 46147 | B19: Cecilia Ramírez Suttclife | C19: 1 minoxidil | D19: 2500 | E19: AMEX | F19: si
A20: 46147 | B20: Cecilia Ramírez Suttclife | C20: liauronidaza | D20: 3000 | E20: AMEX | F20: si
A21: 46147 | B21: Cecilia Ramírez Suttclife | C21: tizo 3 | D21: 1200 | E21: AMEX | F21: si
A22: 46147 | B22: Moshe Chocron Benabou | C22: PV | D22: 1640 | E22: TARJETA CREDITO | F22: no | J22: tenia s/f 29/04/
A23: 46147 | B23: Claudia Maribel Pérez Hernandez | C23: botox | D23: 6500 | E23: visa | F23: no
A24: 46147 | B24: Javier sayrols Bouigue | C24: PV | D24: 1800 | E24: EFECTIVO | F24: no | J24: Saldo a favor$200
A25: 46147 | B25: Gustavo Adolfo Espinosa Carbajal | C25: subsecuente | D25: 0 | E25: CORTESÍA
A26: 46147 | B26: Laura Duhart Gutiérrez | C26: CD dermico loción capilar | D26: 800 | E26: TRANSFERENCIA | F26: no
A27: 46148 | B27: Tamara Beatriz Muñoz Delgadillo | C27: consulta | D27: 1800 | E27: TARJETA CREDITO | F27: si
A28: 46148 | B28: Tamara Beatriz Muñoz Delgadillo | C28: skin glow | D28: 1300 | E28: TARJETA CREDITO | F28: si
A29: 46148 | B29: Tamara Beatriz Muñoz Delgadillo | C29: solución | D29: 500 | E29: TARJETA CREDITO | F29: si | J29: pend, entregar sol.
A30: 46148 | B30: Soylo Montes de Oca Olguín | C30: subsecuente | D30: 1800 | E30: TARJETA CREDITO | F30: si
A31: 46148 | B31: Mariana Evelyn Carrillo González | C31: botox | D31: 5850 | E31: EFECTIVO
A32: 46148 | B32: Mariana Evelyn Carrillo González | C32: vastionin | D32: 1000 | E32: EFECTIVO
A33: 46148 | B33: Kiyomi Alvarado Tanamachi | C33: subsecuente | D33: 1800 | E33: TARJETA CREDITO | F33: no
A34: 46148 | B34: Zeltzin Rosas Espinoza | C34: retoque | D34: 0 | E34: CORTESÍA
A35: 46148 | B35: Ledicia Benabou Benmaman | C35: subsecuente | D35: 1800 | E35: EFECTIVO | F35: no
A36: 46148 | B36: Araceli Plaza Vázquez | C36: acido hiauloronico/radiesse | D36: 21250 | E36: TARJETA CREDITO | F36: no
A37: 46148 | B37: Miguel Angel Tejeda Calvario | C37: ssubsecuente | D37: 0 | E37: CORTESÍA
A38: 46148 | B38: Diana Neri Neri | C38: PV/BOTOX | D38: 5525 | E38: TARJETA CREDITO | F38: si
A39: 46148 | B39: Carlos Figueroa Cobos | C39: BOTOX | D39: 5525 | E39: TARJETA CREDITO | F39: si
A40: 46148 | B40: Ximena Gomez Leites | C40: PV | D40: 1800 | E40: TARJETA CREDITO | F40: no
A41: 46148 | B41: Ximena Gomez Leites | C41: pastillas | D41: 1000 | E41: TARJETA CREDITO | F41: no
A42: 46148 | B42: Grecia Moreno | C42: botox | D42: 3500 | E42: TARJETA CREDITO | F42: no
A43: 46148 | B43: Grecia Moreno | C43: pastillas | D43: 1000 | E43: TARJETA CREDITO | F43: no
A44: 46149 | B44: Diana Morgado Iglesias | C44: 1 minoxidil 1 mg | D44: 2500 | E44: TARJETA CREDITO | F44: no | J44: se cobro dr.Barrera
A45: 46149 | B45: Paola Huelga Correa | C45: Subsecuente | D45: 1800 | E45: AMEX | F45: no | J45: pago Pen. 04/07 | K45: se cobro dr.Barrera 7/5/26
...

Sheet DR. CARLOS
A7: DR. CARLOS BARRERA
A8: FECHA | B8: NOMBRE DEL PACIENTE | C8: TIPO DE CONSULTA | D8: MONTO | E8: MEDIO DE PAGO | F8: FACTURADO | G8: NÚMERO RECIBO | H8: NÚMERO FACTURA | I8: FUENTE | J8: OBSERVACIONES
A9: 46144 | B9: Jorge Eduardo Rodríguez Loera | C9: retoque | D9: 0 | E9: CORTESÍA | F9: no
A10: 46144 | B10: Jorge Rodolfo Escamilla Torres | C10: Botox | D10: 6500 | E10: TARJETA CREDITO | F10: si | H10: A 9 | J10: Saldo a a favor $500
A11: 46144 | B11: Juan Carlos Guzman Solis | C11: procedimiento | D11: 2500 | E11: TARJETA DEBITO | F11: no
A12: 46144 | B12: Juan Carlos Guzman Solis | C12: 1 polaris + 3 minoxidil 5 | D12: 2800 | E12: TARJETA DEBITO | F12: no
A13: 46144 | B13: Jorge Gerardo Cruz Aguila | C13: inyecciones de dutasteride | D13: 2500 | E13: TARJETA CREDITO | F13: si | H13: A 10 | J13: envio CSF
A14: 46144 | B14: Paula Islas Cantu | C14: Subsecuente | D14: 1800 | E14: TARJETA CREDITO | F14: si | H14: A 14 | J14: factura solicitada
A15: 46144 | B15: Ana Guadalupe Gúzman Ariza | C15: luz pulsada | D15: 2500 | E15: TARJETA DEBITO | F15: NO
A16: 46144 | B16: Fabiola Flores Guadarrama | C16: PV | D16: 2000 | E16: TARJETA CREDITO | F16: no
A17: 46144 | B17: Fabiola Flores Guadarrama | C17: Mesoterapia | D17: 2500 | E17: TARJETA CREDITO | F17: no
A18: 46144 | B18: Fabiola Flores Guadarrama | C18: Polaris | D18: 1000 | E18: TARJETA CREDITO | F18: no
A19: 46144 | B19: María del Carmen Crespo Pozuelo | C19: PV | D19: 0 | E19: CORTESÍA
A20: 46146 | B20: Sharon Esquenazi Opatowski | C20: PV | D20: 2000 | E20: TARJETA CREDITO | F20: SI | H20: A 11 | J20: Factura soliicitada
A21: 46146 | B21: Claudia Perez Roldan | C21: sculptra | D21: 12500 | E21: TARJETA CREDITO | F21: SI | H21: A12 | J21: Factura soliicitada
A22: 46146 | B22: Tadeo Maximiliano Vargas Espinosa | C22: inyección de dutasteride | D22: 3000 | E22: TARJETA CREDITO | F22: Si | H22: PEND CSF | J22: Factura soliicitada
A23: 46146 | B23: Tadeo Maximiliano Vargas Espinosa | C23: 1 polaris + 4 minoxidil 5 | D23: 4900 | E23: TARJETA CREDITO | F23: si | J23: Factura soliicitada
A24: 46146 | B24: Alejandra Arocha Garreño | C24: Subsecuente | D24: 2000 | E24: TARJETA CREDITO | F24: NO
A25: 46146 | B25: Iñaki Alvarez Arocha | C25: PV | D25: 2000 | E25: TARJETA CREDITO | F25: NO
A26: 46147 | B26: Mauricio Alejandro Macias Ocaña | C26: 2 polaris | D26: 2000 | E26: TARJETA CREDITO | F26: si | H26: A13
A27: 46147 | B27: Valeria Garcia Herrerias | C27: PV | D27: 2000 | E27: TRANSFERENCIA | F27: si | H27: A 8
A28: 46147 | B28: Valeria Garcia Herrerias | C28: 3 minoxidil 1 mg | D28: 2800 | E28: TRANSFERENCIA | F28: si | H28: A 8
A29: 46147 | B29: Valeria Hernández Sánchez | C29: Subsecuente | D29: 0 | E29: CORTESÍA
A30: 46147 | B30: Alejandra Martinez Perez | C30: retoque | D30: 0
A31: 46147 | B31: Celia Masri Maya | C31: Subsecuente | D31: 1800 | E31: TARJETA CREDITO | F31: no
A32: 46147 | B32: Celia Masri Maya | C32: 1 epuris | D32: 1200 | E32: TARJETA CREDITO | F32: no | J32: saldo a favor $400
A33: 46147 | B33: Laura Poucel Maldonado | C33: PV | D33: 2000 | E33: TARJETA CREDITO | F33: si | H33: A 19
A34: 46147 | B34: Laura Poucel Maldonado | C34: 1 polaris + 1minoxidel 1mg | D34: 2100 | E34: TARJETA CREDITO | F34: si | H34: A 19
A35: 46147 | B35: Emiliano Cortina Saviñón | C35: PV | D35: 2000 | E35: TARJETA CREDITO | F35: no
A36: 46147 | B36: Luis Enrique Rodríguez Sánchez | C36: botox | D36: 6000 | E36: TARJETA CREDITO | F36: no
A37: 46147 | B37: Luis Enrique Rodríguez Sánchez | C37: profhilo | D37: 8000 | E37: TARJETA CREDITO | F37: no
A38: 46147 | B38: SOFIA AUXILIADORA RODRIGUEZ RODRIGUEZ | C38: profhilo | D38: 8000 | E38: TARJETA CREDITO | F38: no
A39: 46147 | B39: Begoña Elizalde | C39: PV | D39: 2000 | E39: EFECTIVO | F39: no
A40: 46147 | B40: Begoña Elizalde | C40: 1 minoxidil de 1mg | D40: 1100 | E40: EFECTIVO | F40: no
A41: 46147 | B41: Ángel Manuel García Ochoa | C41: Subsecuente | D41: 1800 | E41: TARJETA CREDITO | F41: no
A42: 46147 | B42: Ángel Manuel García Ochoa | C42: dutasteride | D42: 2500 | E42: TARJETA CREDITO | F42: no
A43: 46147 | B43: Ángel Manuel García Ochoa | C43: 3 polaris + 3 minoxidil de 5mg | D43: 5800 | E43: TARJETA CREDITO | F43: no
A44: 46147 | B44: Karla Melina Mendoza Rodriguez | C44: exosomas | D44: 4000 | E44: TARJETA CREDITO | F44: no
A45: 46147 | B45: Daniel Barrera Ochoa | C45: 2 minoxidil 5mg (90 caps) | D45: 0 | E45: CORTESÍA
A46: 46147 | B46: Gabriel Guaida | C46: 1 minoxidol 5m | D46: 1100 | E46: TARJETA CREDITO | F46: si | H46: A 7
...

Sheet COSM. KARELY
A7: KARELY
A8: FECHA | B8: NOMBRE DEL PACIENTE | C8: TIPO DE CONSULTA | D8: MONTO | E8: MEDIO DE PAGO | F8: FACTURADO | G8: NÚMERO RECIBO | H8: NÚMERO FACTURA | I8: FUENTE | J8: OBSERVACIONES
A9: 46144 | B9: Eduardo Rios Vivero | C9: limpieza facial | D9: 1200 | E9: TARJETA CREDITO | F9: no | J9: cobro dr, Carlos
A10: 46144 | B10: Mariam Gutierrez | C10: dermapen | D10: 3500 | E10: TARJETA CREDITO | F10: no | J10: cobro dra. Ale
A11: 46148 | B11: Natalia Arenas Ortiz | C11: geneo | D11: 2000 | E11: TARJETA CREDITO | F11: no | J11: cobro dr, Carlos
A12: 46149 | B12: Emilia Schvartzman Berman | C12: Hydrafacial | D12: 2125 | E12: AMEX | F12: si | H12: A 15 | J12: cobro dr, Carlos
A13: 46150 | B13: Jesica Smeke Smeke | C13: Luz pulsada | D13: 2000 | E13: TARJETA CREDITO | F13: no | J13: cobro dr, Carlos
A14: 46150 | B14: Mireya Yamile Morales Romo | C14: Hydrafacial | D14: 2720 | E14: EFECTIVO | F14: no
A15: 46150 | B15: Camila Soto | C15: Hydrafacial deluxe | D15: 2720
A16: 46154 | B16: Pamela Guerrero Pérez | C16: Hydrafacial deluxe | D16: 2720 | E16: TARJETA CREDITO | F16: SI | J16: cobro dra. Ale
A17: 46155 | B17: Jazmin Lozano | C17: depilación | D17: 0 | E17: CORTESÍA | J17: 5/de 5 consultas
A18: 46156 | B18: Fabiola Flores Guadarrama | C18: geneo | D18: 2000 | E18: TARJETA CREDITO | F18: no
A19: 46157 | B19: Jack Romano Grimberg | C19: limpieza facial | D19: 1200 | E19: TARJETA CREDITO
A20: 46158 | B20: Juan Alberto Becerra Martínez | C20: Laser M22 | D20: 3500 | E20: TARJETA DEBITO | J20: cobro dra. Ale
A21: 46158 | B21: Alicia Luna Zarate | C21: Hydrafacial deluxe | D21: 2720 | E21: TARJETA CREDITO | J21: cobro dr, Carlos
A22: 46160 | B22: Lucia Escalante Barbabosa | C22: Luz pulsada | D22: 3000 | E22: TARJETA CREDITO | J22: cobro dra. Ale
A23: 46162 | B23: Marcos Rivera Hernandez | C23: depilación laser media cara | D23: 700 | E23: TARJETA DEBITO | J23: cobro dra. Ale
A24: 46164 | B24: Gabriela Buenfil
A25: 46164 | B25: David Corona Balcazar | C25: Hydrafacial signature | D25: 2500 | E25: TARJETA CREDITO
A26: 46168 | B26: Víctor Eduardo Mejia Gonzalez | C26: facial | D26: 1200 | E26: TARJETA CREDITO | J26: cobro dr, Carlos
A27: 46168 | B27: Mariano Alberto Mazariegos Robles | C27: tricopat | D27: 3500 | E27: TARJETA CREDITO | F27: si
A28: 46169 | B28: José David González Romero | C28: tricopat | D28: 3500 | E28: TARJETA CREDITO | F28: no
A29: 46169 | B29: Irene Ambe Sitton | C29: Hydrafacial signature | D29: 2000 | E29: EFECTIVO
A30: 46169 | B30: Irene Ambe Sitton | C30: Hydrafacial signature | D30: 125 | E30: tarjeta
A31: 46170 | B31: Mariana Alcala Robles | C31: CO2 | D31: 2900 | E31: EFECTIVO | F31: no
A32: 46170 | B32: Mariana Alcala Robles | D32: 1600 | E32: TARJETA CREDITO | F32: no
A33: 46170 | B33: Maria Guadalupe Trejo Rodríguez | D33: 3500 | E33: TARJETA CREDITO | F33: si
A34: 46171 | B34: Anais Atilano Velásquez | C34: tricopat | D34: 3500 | E34: TARJETA DEBITO | F34: si

Sheet COSMETOLOGA KARLA.  
A7: Karla
A8: FECHA | B8: NOMBRE DEL PACIENTE | C8: TIPO DE CONSULTA | D8: MONTO | E8: MEDIO DE PAGO | F8: FACTURADO | G8: NÚMERO RECIBO | H8: NÚMERO FACTURA | I8: FUENTE | J8: OBSERVACIONES
A9: 46146 | B9: Miguel Angel Zavala Moreno | C9: Hydrafacial DELUXE | D9: 2720 | E9: AMEX | F9: no | J9: se cobro dr. Carlos
A10: 46146 | B10: Mariana Lopez Anaya | C10: depilacion | D10: 4300 | E10: TARJETA CREDITO | F10: no | J10: se cobro dr. Carlos
A11: 46146 | B11: Luciana Pandal López | C11: depilacion piernas | D11: 1800 | E11: TARJETA CREDITO | F11: no | J11: se cobro dr. Carlos
A12: 46146 | B12: Luciana Pandal López | C12: depilacion bigote | D12: 500 | E12: TARJETA CREDITO | F12: no | J12: se cobro dr. Carlos
A13: 46146 | B13: Karlo Imanuel Galindo Ramírez | C13: limpeza facial | D13: 1200 | E13: TARJETA CREDITO | J13: se cobro dra. Ale
A14: 46147 | B14: Alejandra Martinez Perez | C14: Limpieza e hidratación | D14: 1500 | E14: TARJETA CREDITO | F14: no
A15: 46147 | B15: Lucia Escalante Barbabosa | C15: depilación media cara | D15: 700 | E15: TARJETA CREDITO | F15: no | J15: se cobro dra. Ale
A16: 46147 | B16: Valeria Hernández Sánchez | C16: Hydrafacial DELUXE | D16: 2560 | E16: EFECTIVO | F16: no | J16: caja 2500
A17: 46148 | B17: Maria Isabel Alatorre | C17: limpieza | D17: 1000 | E17: EFECTIVO | F17: no | J17: caja
A18: 46148 | D18: 200 | E18: TARJETA CREDITO | F18: no | J18: se cobro dr.Carlos
A19: 46149 | B19: Marina Cortes García | C19: Depilación cara completa | D19: 1100 | E19: AMEX | F19: no
A20: 46149 | B20: Paola Huelga Correa | C20: limpieza | D20: 1200 | E20: AMEX | F20: no | J20: se cobro dr.Carlos
A21: 46150 | B21: Ander Ovejas | C21: Depilación láser | D21: 1700 | E21: EFECTIVO | F21: no | J21: caja
A22: 46150 | B22: Clara Torres | C22: GENEO | D22: 2000 | E22: AMEX | F22: si
A23: 46150 | B23: Maria Rivero Borrell | C23: limpieza Facial | D23: 1200 | E23: TARJETA CREDITO | F23: no | J23: se cobro dr.Carlos
A24: 46150 | B24: Daphne Yamileth Ugalde Peña | C24: limpieza facial | D24: 1200 | E24: TARJETA DEBITO | F24: no | J24: se cobro dra. Ale
A25: 46150 | B25: Daphne Yamileth Ugalde Peña | C25: Limpieza de espalda | D25: 1200 | E25: TARJETA DEBITO | F25: no | J25: se cobro dra. Ale
A26: 46150 | B26: Abigail Paniagua Vizcarra | C26: Luz pulsada | D26: 3500 | E26: TARJETA CREDITO | F26: no | J26: se cobro dra. Ale
A27: 46151 | B27: Luciano Perez Alonso | C27: facial | D27: 1200 | E27: TARJETA CREDITO | F27: no | J27: se cobro dr.Carlos
A28: 46151 | B28: Alejandra Garcia Vizcaino | C28: Hydrafacial DELUXE | D28: 2720 | E28: TARJETA CREDITO | F28: si | J28: se cobro dr.Carlos
A29: 46151 | B29: Andrea Fornelli | C29: limpeza facial | D29: 1500 | E29: TARJETA CREDITO | F29: no | J29: se cobro dr.Carlos
A30: 46153 | B30: Jannet Martínez Villegas | C30: Luz pulsada | D30: 0 | E30: CORTESÍA | F30: no | J30: pagada 22/04/2026
A31: 46153 | B31: Nicole Antonovich Taunton | C31: limpieza | D31: 1200 | E31: TARJETA CREDITO | F31: no | J31: se cobro dra. Ale
A32: 46154 | B32: Cecilia Marcela Ramírez Suttclife | C32: co2 | D32: 5000 | E32: EFECTIVO | F32: no | J32: Se entrega Efec a la DRA.
A33: 46154 | B33: Cecilia Marcela Ramírez Suttclife | C33: Luz pulsada | D33: 5000 | E33: EFECTIVO | F33: no | J33: Se entrega Efec a la DRA.
A34: 46154 | B34: Jose Senado | C34: Hydrafacial DELUXE | D34: 2720 | E34: TARJETA CREDITO | F34: si | J34: se cobro dra. Ale
... A38: 46155 | B38: Claudia Cristina Barrera Carmona | C38: Depilación de cara completa y axilas | D38: 1950 | E38: TARJETA CREDITO | F38: no | J38: se cobro dr.Carlos
A39: 46157 | B39: Zeltzin Rosas Espinoza | C39: Hydrafacial DELUXE | D39: 2720 | E39: EFECTIVO | F39: NO
A40: 46160 | B40: Paula Andrea Fabrega Roncagliolo | C40: Hydrafacial DELUXE | D40: 3400 | E40: TRANSFERENCIA | F40: no
A41: 46161 | B41: Lizbeth Meléndez Hernández | C41: dermapen | D41: 3500 | E41: TARJETA CREDITO | F41: SI | J41: se cobro dr. Carlos
A42: 46161 | B42: Ledicia Benabou Benmaman | C42: facial
A43: 46162 | B43: Amanda Martínez Alanís | C43: limpieza | D43: 1200 | E43: TARJETA CREDITO | F43: no
A44: 46162 | B44: Elia Annette Bernard Guerrero | C44: geneo | D44: 2000 | E44: TARJETA CREDITO | F44: no
A45: 46162 | B45: Silvana Ramirez Angulo | C45: limpieza | D45: 1000 | E45: TARJETA CREDITO | J45: se cobro dra. Ale
A46: 46162 | B46: Silvana Ramirez Angulo | D46: 200 | E46: EFECTIVO
A47: 46163 | B47: Claudia Cristina Barrera Carmona | C47: Hydrafacial DELUXE | D47: 2720 | E47: TARJETA CREDITO | F47: no | J47: se cobro dr Carlos
A48: 46163 | B48: Fernanda Arroyo Aldana | C48: Hydrafacial DELUXE | D48: 2720 | E48: TARJETA CREDITO | F48: no | J48: se cobro dr Carlos
A49: 46164 | B49: Kelin Areli Olvera Quiroz | C49: limpieza facial profunda | D49: 1200 | E49: EFECTIVO | F49: no | J49: caja
...

Sheet CIERRE DIARIO
A7: FECHA
A8: 46176
A10: EQUIPO | B10: AMEX | C10: EFECTIVO | D10: TARJETA CREDITO | E10: TARJETA DEBITO | F10: TRANSFERENCIA | G10: TOTAL
A11: DRA. ALEJANDRA GUERRERO | B11: =+SUMIFS(BD_ALEJANDRA[MONTO],BD_ALEJANDRA[MEDIO DE PAGO],'CIERRE DIARIO'!$B$10,BD_ALEJANDRA[FECHA],'CIERRE DIARIO'!$A$8) -> 0 | C11: =+SUMIFS(BD_ALEJANDRA[MONTO],BD_ALEJANDRA[MEDIO DE PAGO],$C$10,BD_ALEJANDRA[FECHA],'CIERRE DIARIO'!$A$8) -> 0 | D11: =+SUMIFS(BD_ALEJANDRA[MONTO],BD_ALEJANDRA[MEDIO DE PAGO],$D$10,BD_ALEJANDRA[FECHA],'CIERRE DIARIO'!$A$8) -> 0 | E11: =+SUMIFS(BD_ALEJANDRA[[#All],[MONTO]],BD_ALEJANDRA[[#All],[MEDIO DE PAGO]],'CIERRE DIARIO'!$E$10,BD_ALEJANDRA[[#All],[FECHA]],'CIERRE DIARIO'!$A$8) -> 0 | F11: =+SUMIFS(BD_ALEJANDRA[[#All],[MONTO]],BD_ALEJANDRA[[#All],[MEDIO DE PAGO]],$F$10,BD_ALEJANDRA[[#All],[FECHA]],'CIERRE DIARIO'!$A$8) -> 0 | G11: =+SUM(B11:F11) -> 0
A12: DR. CARLOS BARRERA | B12: =+SUMIFS(BD_CARLOS[MONTO],BD_CARLOS[MEDIO DE PAGO],'CIERRE DIARIO'!$B$10,BD_CARLOS[FECHA],'CIERRE DIARIO'!$A$8) -> 0 | C12: =+SUMIFS(BD_CARLOS[MONTO],BD_CARLOS[MEDIO DE PAGO],$C$10,BD_CARLOS[FECHA],'CIERRE DIARIO'!$A$8) -> 0 | D12: =+SUMIFS(BD_CARLOS[MONTO],BD_CARLOS[MEDIO DE PAGO],$D$10,BD_CARLOS[FECHA],'CIERRE DIARIO'!$A$8) -> 0 | E12: =+SUMIFS(BD_CARLOS[[#All],[MONTO]],BD_CARLOS[[#All],[MEDIO DE PAGO]],'CIERRE DIARIO'!$E$10,BD_CARLOS[[#All],[FECHA]],'CIERRE DIARIO'!$A$8) -> 0 | F12: =+SUMIFS(BD_CARLOS[[#All],[MONTO]],BD_CARLOS[[#All],[MEDIO DE PAGO]],$F$10,BD_CARLOS[[#All],[FECHA]],'CIERRE DIARIO'!$A$8) -> 0 | G12: =+SUM(B12:F12) -> 0
A13: COSM. KARELY MONTES | B13: =+SUMIFS(BD_COSM1[MONTO],BD_COSM1[MEDIO DE PAGO],'CIERRE DIARIO'!$B$10,BD_COSM1[FECHA],'CIERRE DIARIO'!$A$8) -> 0 | C13: =+SUMIFS(BD_COSM1[MONTO],BD_COSM1[MEDIO DE PAGO],$C$10,BD_COSM1[FECHA],'CIERRE DIARIO'!$A$8) -> 0 | D13: =+SUMIFS(BD_COSM1[MONTO],BD_COSM1[MEDIO DE PAGO],$D$10,BD_COSM1[FECHA],'CIERRE DIARIO'!$A$8) -> 0 | E13: =+SUMIFS(BD_COSM1[[#All],[MONTO]],BD_COSM1[[#All],[MEDIO DE PAGO]],'CIERRE DIARIO'!$E$10,BD_COSM1[[#All],[FECHA]],'CIERRE DIARIO'!$A$8) -> 0 | F13: =+SUMIFS(BD_COSM1[[#All],[MONTO]],BD_COSM1[[#All],[MEDIO DE PAGO]],$F$10,BD_COSM1[[#All],[FECHA]],'CIERRE DIARIO'!$A$8) -> 0 | G13: =+SUM(B13:F13) -> 0
A14: COSM. KARLA | B14: =+SUMIFS(BD_COSM2[MONTO],BD_COSM2[MEDIO DE PAGO],'CIERRE DIARIO'!$B$10,BD_COSM2[FECHA],'CIERRE DIARIO'!$A$8) -> 0 | C14: =+SUMIFS(BD_COSM2[MONTO],BD_COSM2[MEDIO DE PAGO],$C$10,BD_COSM2[FECHA],'CIERRE DIARIO'!$A$8) -> 0 | D14: =+SUMIFS(BD_COSM2[MONTO],BD_COSM2[MEDIO DE PAGO],$D$10,BD_COSM2[FECHA],'CIERRE DIARIO'!$A$8) -> 0 | E14: =+SUMIFS(BD_COSM2[[#All],[MONTO]],BD_COSM2[[#All],[MEDIO DE PAGO]],'CIERRE DIARIO'!$E$10,BD_COSM2[[#All],[FECHA]],'CIERRE DIARIO'!$A$8) -> 0 | F14: =+SUMIFS(BD_COSM2[[#All],[MONTO]],BD_COSM2[[#All],[MEDIO DE PAGO]],$F$10,BD_COSM2[[#All],[FECHA]],'CIERRE DIARIO'!$A$8) -> 0 | G14: =+SUM(B14:F14) -> 0
A16: TOTAL | B16: =+SUM(B11:B14) -> 0 | C16: =+SUM(C11:C14) -> 0 | D16: =+SUM(D11:D14) -> 0 | E16: =+SUM(E11:E14) -> 0 | F16: =+SUM(F11:F14) -> 0 | G16: =+SUM(G11:G14) -> 0

Sheet INVENTARIO
A1: {=A1:Q38} -> 0 | E1: INVENTARIO DE MEDICAMENTOS DR. BARRERA
A3: PRODUCTO | B3: FECHA
B4: 46174
A5: Minoxidil 2.5 mg | B5: 24
A6: Minoxidil 5 mg | B6: 18
A7: Minoxidil 5 mg c/90 tab | B7: 7
A8: Minoxidil 1 mg | B8: 18
A9: Polaris | B9: 15
A10: Folcare | B10: 0
A11: Capilarium CAPIXYL | B11: 5
A12: Capilarium MINOXIDIL | B12: 9
A13: Dutasteride | B13: 22
A14: Epuris | B14: 17
A15: Acido Trexamico | B15: 0
A16: Nourkrim | B16: 0
... A20: Gel sebiaclear | B20: 5
A22: PRODUCTO | B22: FECHA | C22: INGRESOS | D22: FECHA | E22: INGRESOS | F22: INGRESOS | G22: FECHA | H22: FECHA | I22: FECHA | J22: INGRESOS | K22: INGRESOS | L22: FECHA | M22: INGRESOS | N22: INGRESOS | O22: FECHA | P22: INGRESOS | Q22: fecha
A23: Minoxidil 2.5 mg
A24: Minoxidil 5 mg
A25: Minoxidil 5 mg c/90 tab
A26: Minoxidil 1 mg
A27: Polaris
A28: Folcare
A29: Capilarium CAPIXYL
A30: Capilarium MINOXIDIL
A31: Dutasteride
A32: Epuris
A33: Acido Trexamico
A34: Nourkrim
... A38: Gel sebiaclear
A39: PRODUCTO | B39: FECHA | C39: INGRESOS | D39: FECHA | E39: INGRESOS | F39: INGRESOS | G39: FECHA | H39: FECHA | I39: FECHA | J39: INGRESOS | K39: INGRESOS | L39: FECHA | M39: INGRESOS | N39: INGRESOS | O39: FECHA | P39: INGRESOS | Q39: fecha
B40: 46118 | D40: 46125 | E40: 46125 | F40: 46127 | G40: 46132 | H40: 46140 | I40: 46147 | J40: 46149 | K40: 46154 | L40: 46156 | M40: 46156 | N40: 46157 | O40: 46160 | P40: 46170 | Q40: 46167
A41: Minoxidil 2.5 mg | B41: 3 | D41: 19 | F41: 20 | G41: 38 | H41: 31 | I41: 30 | L41: 22 | O41: 19 | P41: 25 | Q41: 12
A42: Minoxidil 5 mg | B42: 25 | D42: 40 | F42: 40 | G42: 72 | H42: 66 | I42: 54 | L42: 42 | O42: 37 | Q42: 31
A43: Minoxidil 5 mg c/90 tab | B43: 10 | D43: 9 | G43: 9 | H43: 9 | I43: 9 | L43: 7 | O43: 7 | Q43: 7
A44: Minoxidil 1 mg | B44: 28 | D44: 1 | F44: 40 | G44: 37 | H44: 30 | I44: 25 | L44: 8 | N44: 30 | O44: 31 | Q44: 28
A45: Polaris | B45: 20 | D45: 0 | E45: 40 | G45: 36 | H45: 25 | I45: 13 | J45: 40 | L45: 42 | O45: 29 | Q45: 23
A46: Folcare | B46: 0 | D46: 0 | G46: 0 | H46: 0 | I46: 0 | L46: 0 | O46: 0 | Q46: 0
A47: Capilarium CAPIXYL | B47: 0 | D47: 0 | G47: 0 | H47: 0 | I47: 0 | K47: 20 | L47: 10 | O47: 9 | Q47: 8
A48: Capilarium MINOXIDIL | M48: 20 | O48: 15 | Q48: 12
...

Sheet Listas
A1: DOCTOR | B1: TIPO CONSULTA | C1: MEDIOS DE PAGO | D1: FUENTE
A2: DRA. ALEJANDRA GUERRERO | B2: PRIMERA VEZ | C2: AMEX | D2: DOCTORALIA
A3: DR. CARLOS BARRERA | B3: SUBSECUENTE | C3: CORTESÍA | D3: GOOGLE
A4: COSM. KARELY MONTES | C4: EFECTIVO | D4: RECOMENDACIÓN
C5: PAGADO | D5: RRSS
C6: TARJETA CREDITO
C7: TARJETA DEBITO
C8: TRANSFERENCIA
